2015-09-08 20:25:32,684 - project - ERROR - Exception on /dashboard [GET]
Traceback (most recent call last):
  File "C:\Users\Alessio\icollectweb\env\lib\site-packages\flask\app.py", line 1817, in wsgi_app
    response = self.full_dispatch_request()
  File "C:\Users\Alessio\icollectweb\env\lib\site-packages\flask\app.py", line 1477, in full_dispatch_request
    rv = self.handle_user_exception(e)
  File "C:\Users\Alessio\icollectweb\env\lib\site-packages\flask\app.py", line 1381, in handle_user_exception
    reraise(exc_type, exc_value, tb)
  File "C:\Users\Alessio\icollectweb\env\lib\site-packages\flask\app.py", line 1475, in full_dispatch_request
    rv = self.dispatch_request()
  File "C:\Users\Alessio\icollectweb\env\lib\site-packages\flask\app.py", line 1461, in dispatch_request
    return self.view_functions[rule.endpoint](**req.view_args)
  File "C:\Users\Alessio\icollectweb\project\general\view.py", line 24, in wrap
    return test(*args, **kwargs)
  File "C:\Users\Alessio\icollectweb\project\general\view.py", line 41, in dashboard_
    return render_template('dashboard_.html', username=session['user'], current_time=datetime.utcnow())
  File "C:\Users\Alessio\icollectweb\env\lib\site-packages\flask\templating.py", line 128, in render_template
    context, ctx.app)
  File "C:\Users\Alessio\icollectweb\env\lib\site-packages\flask\templating.py", line 110, in _render
    rv = template.render(context)
  File "C:\Users\Alessio\icollectweb\env\lib\site-packages\jinja2\environment.py", line 989, in render
    return self.environment.handle_exception(exc_info, True)
  File "C:\Users\Alessio\icollectweb\env\lib\site-packages\jinja2\environment.py", line 754, in handle_exception
    reraise(exc_type, exc_value, tb)
  File "C:\Users\Alessio\icollectweb\project\templates\dashboard_.html", line 1, in top-level template code
    {% extends 'base_.html' %}
  File "C:\Users\Alessio\icollectweb\project\templates\base_.html", line 477, in top-level template code
    <a href="{{ url_for('user.edit_users') }}"><i class="fa fa-fw fa-user"></i> Profile</a>
  File "C:\Users\Alessio\icollectweb\env\lib\site-packages\flask\helpers.py", line 312, in url_for
    return appctx.app.handle_url_build_error(error, endpoint, values)
  File "C:\Users\Alessio\icollectweb\env\lib\site-packages\flask\app.py", line 1641, in handle_url_build_error
    reraise(exc_type, exc_value, tb)
  File "C:\Users\Alessio\icollectweb\env\lib\site-packages\flask\helpers.py", line 305, in url_for
    force_external=external)
  File "C:\Users\Alessio\icollectweb\env\lib\site-packages\werkzeug\routing.py", line 1678, in build
    raise BuildError(endpoint, values, method)
BuildError: ('user.edit_users', {}, None)
2015-09-08 20:25:32,684 - project - ERROR - Exception on /dashboard [GET]
Traceback (most recent call last):
  File "C:\Users\Alessio\icollectweb\env\lib\site-packages\flask\app.py", line 1817, in wsgi_app
    response = self.full_dispatch_request()
  File "C:\Users\Alessio\icollectweb\env\lib\site-packages\flask\app.py", line 1477, in full_dispatch_request
    rv = self.handle_user_exception(e)
  File "C:\Users\Alessio\icollectweb\env\lib\site-packages\flask\app.py", line 1381, in handle_user_exception
    reraise(exc_type, exc_value, tb)
  File "C:\Users\Alessio\icollectweb\env\lib\site-packages\flask\app.py", line 1475, in full_dispatch_request
    rv = self.dispatch_request()
  File "C:\Users\Alessio\icollectweb\env\lib\site-packages\flask\app.py", line 1461, in dispatch_request
    return self.view_functions[rule.endpoint](**req.view_args)
  File "C:\Users\Alessio\icollectweb\project\general\view.py", line 24, in wrap
    return test(*args, **kwargs)
  File "C:\Users\Alessio\icollectweb\project\general\view.py", line 41, in dashboard_
    return render_template('dashboard_.html', username=session['user'], current_time=datetime.utcnow())
  File "C:\Users\Alessio\icollectweb\env\lib\site-packages\flask\templating.py", line 128, in render_template
    context, ctx.app)
  File "C:\Users\Alessio\icollectweb\env\lib\site-packages\flask\templating.py", line 110, in _render
    rv = template.render(context)
  File "C:\Users\Alessio\icollectweb\env\lib\site-packages\jinja2\environment.py", line 989, in render
    return self.environment.handle_exception(exc_info, True)
  File "C:\Users\Alessio\icollectweb\env\lib\site-packages\jinja2\environment.py", line 754, in handle_exception
    reraise(exc_type, exc_value, tb)
  File "C:\Users\Alessio\icollectweb\project\templates\dashboard_.html", line 1, in top-level template code
    {% extends 'base_.html' %}
  File "C:\Users\Alessio\icollectweb\project\templates\base_.html", line 477, in top-level template code
    <a href="{{ url_for('user.edit_users') }}"><i class="fa fa-fw fa-user"></i> Profile</a>
  File "C:\Users\Alessio\icollectweb\env\lib\site-packages\flask\helpers.py", line 312, in url_for
    return appctx.app.handle_url_build_error(error, endpoint, values)
  File "C:\Users\Alessio\icollectweb\env\lib\site-packages\flask\app.py", line 1641, in handle_url_build_error
    reraise(exc_type, exc_value, tb)
  File "C:\Users\Alessio\icollectweb\env\lib\site-packages\flask\helpers.py", line 305, in url_for
    force_external=external)
  File "C:\Users\Alessio\icollectweb\env\lib\site-packages\werkzeug\routing.py", line 1678, in build
    raise BuildError(endpoint, values, method)
BuildError: ('user.edit_users', {}, None)
